---
title: C28105
ms.date: 11/04/2016
ms.topic: reference
f1_keywords:
- C28105
helpviewer_keywords:
- C28105
ms.assetid: 5afdec78-30eb-470c-980f-93d0cb3e74cc
author: mikeblome
ms.author: mblome
manager: markl
ms.workload:
- multiple
ms.openlocfilehash: 8053149db4b47639bd53961090db6b8bbbef80a9
ms.sourcegitcommit: 485ffaedb1ade71490f11cf05962add1718945cc
ms.translationtype: MT
ms.contentlocale: pt-BR
ms.lasthandoff: 10/16/2019
ms.locfileid: "72448409"
---
# <a name="c28105"></a>C28105
Aviso C28105: vazamento de recurso devido a uma exceção

 O recurso especificado não é liberado quando uma exceção é gerada. A instrução especificada pelo caminho pode gerar uma exceção. Esse aviso é semelhante ao aviso [C28103](../code-quality/c28103.md), exceto que, nesse caso, uma exceção está envolvida.

## <a name="example"></a>Exemplo
 O exemplo de código a seguir gera este aviso:

```
res = KeSaveFloatingPointState(buffer);

res = AllocateResource(Resource);
char *p2 = new char[10]; // could throw

delete[] p2;
FreeResource(Resource)
```

 O exemplo de código a seguir evita esse aviso:

```
res = AllocateResource(Resource);
char *p2;

try {
    p2 = new char[10];
} catch (std::bad_alloc *e) {
    // just handle the throw
    ;
}
FreeResource(Resource)
```
